Workbook

Sheet Metrics (Charts & KPIs)
A24: =COUNTA(Working_Data!A2:A1000) -> 120 | E24: =COUNTIF(Working_Data!U2:U1000,"Active") -> 87 | I24: Insight 1: Attrition in 2024 is primarily driven by employees with shorter tenure, indicating early stage retention.
I25: Insight 2: Engineering & mid level roles show comparatively higher exits, suggesting targeted retention & workload review opportunities.

Sheet Pivot Tables
A2: Joiners Trend for 2024 | D2: Monthly Exit Trend for 2024 | G2: Joiners vs Exits for 2024 (Stacked Bar chart) | M2: Headcount by Function & Level
A16: Helper pivot for Attrition Rate
A17: Exits in 2024 | G17: Attrition Insights - Exits by Function (2024) & Top 3 Functions with Most Exits (2024 only) | J17: Exits by Level (2024) | M17: Exits by Tenure Bracket (2024) | Q17: Exits by Level Group
A20: Attrition Rate Trend for 2024
A21: =(B18/120) -> 0.075

Sheet Working_Data
A1: Emp ID | B1: Full name | C1: Date of joining | D1: Email | E1: Gender | F1: Emp type | G1: Emp status | H1: Designation | I1: Function | J1: Team | K1: Department | L1: Sub department | M1: Reporting manager | N1: Lead POC | O1: Exit date | P1: Joining month | Q1: Exit month | R1: Tenure bracket | S1: Level_Group | T1: Business_unit | U1: Status_Flag | V1: Join_Quarter | W1: Exit_Quarter | X1: Join_Year
A2: EP1000 | B2: Employee 1 | C2: 45871 | D2: ep1000@example.com | E2: Male | F2: Contractor | G2: Relieved | H2: Senior Analyst | I2: Finance | J2: Ops Excellence | K2: FP&A | M2: Mgr 11 | N2: Lead 11 | O2: 45908 | P2: Aug 2025 | Q2: Sep 2025 | R2: <1 year | S2: =IFERROR(VLOOKUP(H2, Level_Map!A:B, 2, FALSE), "") -> L2 | T2: =IFERROR(VLOOKUP(I2, Function_BU_Map!A:B, 2, FALSE), "") -> Corp | U2: =IF(G2="Working","Active","Exited") -> Exited | V2: ="Q"&ROUNDUP(MONTH(C2)/3,0)&" "&YEAR(C2) -> Q3 2025 | W2: =IF(O3="","", "Q"&ROUNDUP(MONTH(O3)/3,0)&" "&YEAR(O3)) | X2: =IF(P2="","",YEAR(C2)) -> 2025
A3: EP1001 | B3: Employee 2 | C3: 44613 | D3: ep1001@example.com | E3: Female | F3: Permanent | G3: Working | H3: Senior Director | I3: Finance | J3: Ops Excellence | K3: Payroll | M3: Mgr 6 | N3: Lead 2 | P3: Feb 2022 | R3: 2–4 years | S3: =IFERROR(VLOOKUP(H3, Level_Map!A:B, 2, FALSE), "") -> L8 | T3: =IFERROR(VLOOKUP(I3, Function_BU_Map!A:B, 2, FALSE), "") -> Corp | U3: =IF(G3="Working","Active","Exited") -> Active | V3: ="Q"&ROUNDUP(MONTH(C3)/3,0)&" "&YEAR(C3) -> Q1 2022 | X3: =IF(P3="","",YEAR(C3)) -> 2022
A4: EP1002 | B4: Employee 3 | C4: 45125 | D4: ep1002@example.com | E4: Male | F4: Permanent | G4: Working | H4: Associate | I4: Product | J4: Ops Excellence | K4: Design | M4: Mgr 10 | N4: Lead 16 | P4: Jul 2023 | R4: 2–4 years | S4: =IFERROR(VLOOKUP(H4, Level_Map!A:B, 2, FALSE), "") -> L3 | T4: =IFERROR(VLOOKUP(I4, Function_BU_Map!A:B, 2, FALSE), "") -> Tech | U4: =IF(G4="Working","Active","Exited") -> Active | V4: ="Q"&ROUNDUP(MONTH(C4)/3,0)&" "&YEAR(C4) -> Q3 2023 | W4: =IF(O4="","", "Q"&ROUNDUP(MONTH(O4)/3,0)&" "&YEAR(O4)) | X4: =IF(P4="","",YEAR(C4)) -> 2023
A5: EP1003 | B5: Employee 4 | C5: 45063 | D5: ep1003@example.com | E5: Male | F5: Permanent | G5: Relieved | H5: Senior Associate | I5: Risk | J5: Wealth | K5: Collections | M5: Mgr 19 | N5: Lead 7 | O5: 45321 | P5: May 2023 | Q5: Jan 2024 | R5: <1 year | S5: =IFERROR(VLOOKUP(H5, Level_Map!A:B, 2, FALSE), "") -> L4 | T5: =IFERROR(VLOOKUP(I5, Function_BU_Map!A:B, 2, FALSE), "") -> Risk | U5: =IF(G5="Working","Active","Exited") -> Exited | V5: ="Q"&ROUNDUP(MONTH(C5)/3,0)&" "&YEAR(C5) -> Q2 2023 | W5: =IF(O5="","", "Q"&ROUNDUP(MONTH(O5)/3,0)&" "&YEAR(O5)) -> Q1 2024 | X5: =IF(P5="","",YEAR(C5)) -> 2023
A6: EP1004 | B6: Employee 5 | C6: 44847 | D6: ep1004@example.com | E6: Male | F6: Permanent | G6: Relieved | H6: Associate | I6: Data | J6: Lending | K6: Data Eng | M6: Mgr 2 | N6: Lead 20 | O6: 45086 | P6: Oct 2022 | Q6: Jun 2023 | R6: <1 year | S6: =IFERROR(VLOOKUP(H6, Level_Map!A:B, 2, FALSE), "") -> L3 | T6: =IFERROR(VLOOKUP(I6, Function_BU_Map!A:B, 2, FALSE), "") -> Tech | U6: =IF(G6="Working","Active","Exited") -> Exited | V6: ="Q"&ROUNDUP(MONTH(C6)/3,0)&" "&YEAR(C6) -> Q4 2022 | W6: =IF(O6="","", "Q"&ROUNDUP(MONTH(O6)/3,0)&" "&YEAR(O6)) -> Q2 2023 | X6: =IF(P6="","",YEAR(C6)) -> 2022
A7: EP1005 | B7: Employee 6 | C7: 45678 | D7: ep1005@example.com | E7: Male | F7: Permanent | G7: Working | H7: Director | I7: CX | J7: Banking | K7: Training | M7: Mgr 8 | N7: Lead 4 | P7: Jan 2025 | R7: <1 year | S7: =IFERROR(VLOOKUP(H7, Level_Map!A:B, 2, FALSE), "") -> L7 | T7: =IFERROR(VLOOKUP(I7, Function_BU_Map!A:B, 2, FALSE), "") -> Ops | U7: =IF(G7="Working","Active","Exited") -> Active | V7: ="Q"&ROUNDUP(MONTH(C7)/3,0)&" "&YEAR(C7) -> Q1 2025 | W7: =IF(O7="","", "Q"&ROUNDUP(MONTH(O7)/3,0)&" "&YEAR(O7)) | X7: =IF(P7="","",YEAR(C7)) -> 2025
A8: EP1006 | B8: Employee 7 | C8: 44740 | D8: ep1006@example.com | E8: Male | F8: Permanent | G8: Working | H8: Senior Director | I8: CX | J8: Ops Excellence | K8: Quality | M8: Mgr 2 | N8: Lead 10 | P8: Jun 2022 | R8: 2–4 years | S8: =IFERROR(VLOOKUP(H8, Level_Map!A:B, 2, FALSE), "") -> L8 | T8: =IFERROR(VLOOKUP(I8, Function_BU_Map!A:B, 2, FALSE), "") -> Ops | U8: =IF(G8="Working","Active","Exited") -> Active | V8: ="Q"&ROUNDUP(MONTH(C8)/3,0)&" "&YEAR(C8) -> Q2 2022 | W8: =IF(O8="","", "Q"&ROUNDUP(MONTH(O8)/3,0)&" "&YEAR(O8)) | X8: =IF(P8="","",YEAR(C8)) -> 2022
A9: EP1007 | B9: Employee 8 | C9: 45771 | D9: ep1007@example.com | E9: Female | F9: Permanent | G9: Working | H9: Analyst | I9: HR | J9: Wealth | K9: Talent Acquisition | M9: Mgr 16 | N9: Lead 13 | P9: Apr 2025 | R9: <1 year | S9: =IFERROR(VLOOKUP(H9, Level_Map!A:B, 2, FALSE), "") -> L1 | T9: =IFERROR(VLOOKUP(I9, Function_BU_Map!A:B, 2, FALSE), "") -> Corp | U9: =IF(G9="Working","Active","Exited") -> Active | V9: ="Q"&ROUNDUP(MONTH(C9)/3,0)&" "&YEAR(C9) -> Q2 2025 | W9: =IF(O9="","", "Q"&ROUNDUP(MONTH(O9)/3,0)&" "&YEAR(O9)) | X9: =IF(P9="","",YEAR(C9)) -> 2025
A10: EP1008 | B10: Employee 9 | C10: 45426 | D10: ep1008@example.com | E10: Male | F10: Intern | G10: Relieved | H10: Associate | I10: Product | J10: Cards | K10: Product Mgmt | M10: Mgr 7 | N10: Lead 9 | O10: 45472 | P10: May 2024 | Q10: Jun 2024 | R10: <1 year | S10: =IFERROR(VLOOKUP(H10, Level_Map!A:B, 2, FALSE), "") -> L3 | T10: =IFERROR(VLOOKUP(I10, Function_BU_Map!A:B, 2, FALSE), "") -> Tech | U10: =IF(G10="Working","Active","Exited") -> Exited | V10: ="Q"&ROUNDUP(MONTH(C10)/3,0)&" "&YEAR(C10) -> Q2 2024 | W10: =IF(O10="","", "Q"&ROUNDUP(MONTH(O10)/3,0)&" "&YEAR(O10)) -> Q2 2024 | X10: =IF(P10="","",YEAR(C10)) -> 2024
A11: EP1009 | B11: Employee 10 | C11: 44623 | D11: ep1009@example.com | E11: Female | F11: Permanent | G11: Working | H11: Manager | I11: Engineering | J11: Banking | K11: Platform | M11: Mgr 1 | N11: Lead 5 | P11: Mar 2022 | R11: 2–4 years | S11: =IFERROR(VLOOKUP(H11, Level_Map!A:B, 2, FALSE), "") -> L5 | T11: =IFERROR(VLOOKUP(I11, Function_BU_Map!A:B, 2, FALSE), "") -> Tech | U11: =IF(G11="Working","Active","Exited") -> Active | V11: ="Q"&ROUNDUP(MONTH(C11)/3,0)&" "&YEAR(C11) -> Q1 2022 | W11: =IF(O11="","", "Q"&ROUNDUP(MONTH(O11)/3,0)&" "&YEAR(O11)) | X11: =IF(P11="","",YEAR(C11)) -> 2022
A12: EP1010 | B12: Employee 11 | C12: 44753 | D12: ep1010@example.com | E12: Female | F12: Permanent | G12: Relieved | H12: Associate | I12: HR | J12: Wealth | K12: People Ops | M12: Mgr 5 | N12: Lead 3 | O12: 45230 | P12: Jul 2022 | Q12: Oct 2023 | R12: 1–2 years | S12: =IFERROR(VLOOKUP(H12, Level_Map!A:B, 2, FALSE), "") -> L3 | T12: =IFERROR(VLOOKUP(I12, Function_BU_Map!A:B, 2, FALSE), "") -> Corp | U12: =IF(G12="Working","Active","Exited") -> Exited | V12: ="Q"&ROUNDUP(MONTH(C12)/3,0)&" "&YEAR(C12) -> Q3 2022 | W12: =IF(O12="","", "Q"&ROUNDUP(MONTH(O12)/3,0)&" "&YEAR(O12)) -> Q4 2023 | X12: =IF(P12="","",YEAR(C12)) -> 2022
A13: EP1011 | B13: Employee 12 | C13: 45038 | D13: ep1011@example.com | E13: Female | F13: Permanent | G13: Working | H13: Senior Director | I13: CX | J13: Ops Excellence | K13: Training | M13: Mgr 5 | N13: Lead 23 | P13: Apr 2023 | R13: 2–4 years | S13: =IFERROR(VLOOKUP(H13, Level_Map!A:B, 2, FALSE), "") -> L8 | T13: =IFERROR(VLOOKUP(I13, Function_BU_Map!A:B, 2, FALSE), "") -> Ops | U13: =IF(G13="Working","Active","Exited") -> Active | V13: ="Q"&ROUNDUP(MONTH(C13)/3,0)&" "&YEAR(C13) -> Q2 2023 | W13: =IF(O13="","", "Q"&ROUNDUP(MONTH(O13)/3,0)&" "&YEAR(O13)) | X13: =IF(P13="","",YEAR(C13)) -> 2023
A14: EP1012 | B14: Employee 13 | C14: 45596 | D14: ep1012@example.com | E14: Female | F14: Permanent | G14: Relieved | H14: Analyst | I14: CX | J14: Lending | K14: Training | M14: Mgr 7 | N14: Lead 17 | O14: 45934 | P14: Oct 2024 | Q14: Oct 2025 | R14: <1 year | S14: =IFERROR(VLOOKUP(H14, Level_Map!A:B, 2, FALSE), "") -> L1 | T14: =IFERROR(VLOOKUP(I14, Function_BU_Map!A:B, 2, FALSE), "") -> Ops | U14: =IF(G14="Working","Active","Exited") -> Exited | V14: ="Q"&ROUNDUP(MONTH(C14)/3,0)&" "&YEAR(C14) -> Q4 2024 | W14: =IF(O14="","", "Q"&ROUNDUP(MONTH(O14)/3,0)&" "&YEAR(O14)) -> Q4 2025 | X14: =IF(P14="","",YEAR(C14)) -> 2024
A15: EP1013 | B15: Employee 14 | C15: 44616 | D15: ep1013@example.com | E15: Male | F15: Permanent | G15: Relieved | H15: Senior Associate | I15: HR | J15: Ops Excellence | K15: L&D | M15: Mgr 13 | N15: Lead 7 | O15: 45795 | P15: Feb 2022 | Q15: May 2025 | R15: 2–4 years | S15: =IFERROR(VLOOKUP(H15, Level_Map!A:B, 2, FALSE), "") -> L4 | T15: =IFERROR(VLOOKUP(I15, Function_BU_Map!A:B, 2, FALSE), "") -> Corp | U15: =IF(G15="Working","Active","Exited") -> Exited | V15: ="Q"&ROUNDUP(MONTH(C15)/3,0)&" "&YEAR(C15) -> Q1 2022 | W15: =IF(O15="","", "Q"&ROUNDUP(MONTH(O15)/3,0)&" "&YEAR(O15)) -> Q2 2025 | X15: =IF(P15="","",YEAR(C15)) -> 2022
A16: EP1014 | B16: Employee 15 | C16: 44969 | D16: ep1014@example.com | E16: Male | F16: Permanent | G16: Working | H16: Manager | I16: HR | J16: Growth | K16: People Ops | M16: Mgr 12 | N16: Lead 12 | P16: Feb 2023 | R16: 2–4 years | S16: =IFERROR(VLOOKUP(H16, Level_Map!A:B, 2, FALSE), "") -> L5 | T16: =IFERROR(VLOOKUP(I16, Function_BU_Map!A:B, 2, FALSE), "") -> Corp | U16: =IF(G16="Working","Active","Exited") -> Active | V16: ="Q"&ROUNDUP(MONTH(C16)/3,0)&" "&YEAR(C16) -> Q1 2023 | W16: =IF(O16="","", "Q"&ROUNDUP(MONTH(O16)/3,0)&" "&YEAR(O16)) | X16: =IF(P16="","",YEAR(C16)) -> 2023
A17: EP1015 | B17: Employee 16 | C17: 45892 | D17: ep1015@example.com | E17: Male | F17: Consultant | G17: Working | H17: Associate | I17: Product | J17: Wealth | K17: Research | M17: Mgr 1 | N17: Lead 20 | P17: Aug 2025 | R17: <1 year | S17: =IFERROR(VLOOKUP(H17, Level_Map!A:B, 2, FALSE), "") -> L3 | T17: =IFERROR(VLOOKUP(I17, Function_BU_Map!A:B, 2, FALSE), "") -> Tech | U17: =IF(G17="Working","Active","Exited") -> Active | V17: ="Q"&ROUNDUP(MONTH(C17)/3,0)&" "&YEAR(C17) -> Q3 2025 | W17: =IF(O17="","", "Q"&ROUNDUP(MONTH(O17)/3,0)&" "&YEAR(O17)) | X17: =IF(P17="","",YEAR(C17)) -> 2025
A18: EP1016 | B18: Employee 17 | C18: 45678 | D18: ep1016@example.com | E18: Male | F18: Permanent | G18: Working | H18: Senior Associate | I18: Engineering | J18: Cards | K18: Platform | M18: Mgr 10 | N18: Lead 12 | P18: Jan 2025 | R18: <1 year | S18: =IFERROR(VLOOKUP(H18, Level_Map!A:B, 2, FALSE), "") -> L4 | T18: =IFERROR(VLOOKUP(I18, Function_BU_Map!A:B, 2, FALSE), "") -> Tech | U18: =IF(G18="Working","Active","Exited") -> Active | V18: ="Q"&ROUNDUP(MONTH(C18)/3,0)&" "&YEAR(C18) -> Q1 2025 | W18: =IF(O18="","", "Q"&ROUNDUP(MONTH(O18)/3,0)&" "&YEAR(O18)) | X18: =IF(P18="","",YEAR(C18)) -> 2025
A19: EP1017 | B19: Employee 18 | C19: 45421 | D19: ep1017@example.com | E19: Male | F19: Permanent | G19: Relieved | H19: Associate | I19: Engineering | J19: Cards | K19: QA | M19: Mgr 12 | N19: Lead 7 | O19: 45563 | P19: May 2024 | Q19: Sep 2024 | R19: <1 year | S19: =IFERROR(VLOOKUP(H19, Level_Map!A:B, 2, FALSE), "") -> L3 | T19: =IFERROR(VLOOKUP(I19, Function_BU_Map!A:B, 2, FALSE), "") -> Tech | U19: =IF(G19="Working","Active","Exited") -> Exited | V19: ="Q"&ROUNDUP(MONTH(C19)/3,0)&" "&YEAR(C19) -> Q2 2024 | W19: =IF(O19="","", "Q"&ROUNDUP(MONTH(O19)/3,0)&" "&YEAR(O19)) -> Q3 2024 | X19: =IF(P19="","",YEAR(C19)) -> 2024
A20: EP1018 | B20: Employee 19 | C20: 45481 | D20: ep1018@example.com | E20: Male | F20: Permanent | G20: Working | H20: Manager | I20: Product | J20: Banking | K20: Product Mgmt | M20: Mgr 5 | N20: Lead 1 | P20: Jul 2024 | R20: 1–2 years | S20: =IFERROR(VLOOKUP(H20, Level_Map!A:B, 2, FALSE), "") -> L5 | T20: =IFERROR(VLOOKUP(I20, Function_BU_Map!A:B, 2, FALSE), "") -> Tech | U20: =IF(G20="Working","Active","Exited") -> Active | V20: ="Q"&ROUNDUP(MONTH(C20)/3,0)&" "&YEAR(C20) -> Q3 2024 | W20: =IF(O20="","", "Q"&ROUNDUP(MONTH(O20)/3,0)&" "&YEAR(O20)) | X20: =IF(P20="","",YEAR(C20)) -> 2024
A21: EP1019 | B21: Employee 20 | C21: 45768 | D21: ep1019@example.com | E21: Female | F21: Permanent | G21: Working | H21: Senior Analyst | I21: CX | J21: Growth | K21: Quality | M21: Mgr 11 | N21: Lead 24 | P21: Apr 2025 | R21: <1 year | S21: =IFERROR(VLOOKUP(H21, Level_Map!A:B, 2, FALSE), "") -> L2 | T21: =IFERROR(VLOOKUP(I21, Function_BU_Map!A:B, 2, FALSE), "") -> Ops | U21: =IF(G21="Working","Active","Exited") -> Active | V21: ="Q"&ROUNDUP(MONTH(C21)/3,0)&" "&YEAR(C21) -> Q2 2025 | W21: =IF(O21="","", "Q"&ROUNDUP(MONTH(O21)/3,0)&" "&YEAR(O21)) | X21: =IF(P21="","",YEAR(C21)) -> 2025
A22: EP1020 | B22: Employee 21 | C22: 45131 | D22: ep1020@example.com | E22: Male | F22: Permanent | G22: Working | H22: Associate | I22: Product | J22: Growth | K22: Design | M22: Mgr 16 | N22: Lead 1 | P22: Jul 2023 | R22: 2–4 years | S22: =IFERROR(VLOOKUP(H22, Level_Map!A:B, 2, FALSE), "") -> L3 | T22: =IFERROR(VLOOKUP(I22, Function_BU_Map!A:B, 2, FALSE), "") -> Tech | U22: =IF(G22="Working","Active","Exited") -> Active | V22: ="Q"&ROUNDUP(MONTH(C22)/3,0)&" "&YEAR(C22) -> Q3 2023 | W22: =IF(O22="","", "Q"&ROUNDUP(MONTH(O22)/3,0)&" "&YEAR(O22)) | X22: =IF(P22="","",YEAR(C22)) -> 2023
A23: EP1021 | B23: Employee 22 | C23: 44575 | D23: ep1021@example.com | E23: Male | F23: Permanent | G23: Relieved | H23: Associate | I23: Finance | J23: Wealth | K23: Accounting | M23: Mgr 3 | N23: Lead 19 | O23: 44931 | P23: Jan 2022 | Q23: Jan 2023 | R23: <1 year | S23: =IFERROR(VLOOKUP(H23, Level_Map!A:B, 2, FALSE), "") -> L3 | T23: =IFERROR(VLOOKUP(I23, Function_BU_Map!A:B, 2, FALSE), "") -> Corp | U23: =IF(G23="Working","Active","Exited") -> Exited | V23: ="Q"&ROUNDUP(MONTH(C23)/3,0)&" "&YEAR(C23) -> Q1 2022 | W23: =IF(O23="","", "Q"&ROUNDUP(MONTH(O23)/3,0)&" "&YEAR(O23)) -> Q1 2023 | X23: =IF(P23="","",YEAR(C23)) -> 2022
A24: EP1022 | B24: Employee 23 | C24: 45427 | D24: ep1022@example.com | E24: Male | F24: Permanent | G24: Working | H24: Senior Manager | I24: Data | J24: Lending | K24: Data Science | M24: Mgr 18 | N24: Lead 23 | P24: May 2024 | R24: 1–2 years | S24: =IFERROR(VLOOKUP(H24, Level_Map!A:B, 2, FALSE), "") -> L6 | T24: =IFERROR(VLOOKUP(I24, Function_BU_Map!A:B, 2, FALSE), "") -> Tech | U24: =IF(G24="Working","Active","Exited") -> Active | V24: ="Q"&ROUNDUP(MONTH(C24)/3,0)&" "&YEAR(C24) -> Q2 2024 | W24: =IF(O24="","", "Q"&ROUNDUP(MONTH(O24)/3,0)&" "&YEAR(O24)) | X24: =IF(P24="","",YEAR(C24)) -> 2024
A25: EP1023 | B25: Employee 24 | C25: 45258 | D25: ep1023@example.com | E25: Male | F25: Permanent | G25: Working | H25: Senior Director | I25: Engineering | J25: Lending | K25: QA | M25: Mgr 17 | N25: Lead 2 | P25: Nov 2023 | R25: 1–2 years | S25: =IFERROR(VLOOKUP(H25, Level_Map!A:B, 2, FALSE), "") -> L8 | T25: =IFERROR(VLOOKUP(I25, Function_BU_Map!A:B, 2, FALSE), "") -> Tech | U25: =IF(G25="Working","Active","Exited") -> Active | V25: ="Q"&ROUNDUP(MONTH(C25)/3,0)&" "&YEAR(C25) -> Q4 2023 | W25: =IF(O25="","", "Q"&ROUNDUP(MONTH(O25)/3,0)&" "&YEAR(O25)) | X25: =IF(P25="","",YEAR(C25)) -> 2023
A26: EP1024 | B26: Employee 25 | C26: 45131 | D26: ep1024@example.com | E26: Other | F26: Contractor | G26: Working | H26: Senior Analyst | I26: CX | J26: Cards | K26: Training | M26: Mgr 16 | N26: Lead 3 | P26: Jul 2023 | R26: 2–4 years | S26: =IFERROR(VLOOKUP(H26, Level_Map!A:B, 2, FALSE), "") -> L2 | T26: =IFERROR(VLOOKUP(I26, Function_BU_Map!A:B, 2, FALSE), "") -> Ops | U26: =IF(G26="Working","Active","Exited") -> Active | V26: ="Q"&ROUNDUP(MONTH(C26)/3,0)&" "&YEAR(C26) -> Q3 2023 | W26: =IF(O26="","", "Q"&ROUNDUP(MONTH(O26)/3,0)&" "&YEAR(O26)) | X26: =IF(P26="","",YEAR(C26)) -> 2023
A27: EP1025 | B27: Employee 26 | C27: 44880 | D27: ep1025@example.com | E27: Female | F27: Permanent | G27: Working | H27: Senior Analyst | I27: HR | J27: Cards | K27: L&D | M27: Mgr 3 | N27: Lead 16 | P27: Nov 2022 | R27: 2–4 years | S27: =IFERROR(VLOOKUP(H27, Level_Map!A:B, 2, FALSE), "") -> L2 | T27: =IFERROR(VLOOKUP(I27, Function_BU_Map!A:B, 2, FALSE), "") -> Corp | U27: =IF(G27="Working","Active","Exited") -> Active | V27: ="Q"&ROUNDUP(MONTH(C27)/3,0)&" "&YEAR(C27) -> Q4 2022 | W27: =IF(O27="","", "Q"&ROUNDUP(MONTH(O27)/3,0)&" "&YEAR(O27)) | X27: =IF(P27="","",YEAR(C27)) -> 2022
A28: EP1026 | B28: Employee 27 | C28: 45002 | D28: ep1026@example.com | E28: Male | F28: Permanent | G28: Working | H28: Senior Associate | I28: Engineering | J28: Growth | K28: QA | M28: Mgr 16 | N28: Lead 9 | P28: Mar 2023 | R28: 2–4 years | S28: =IFERROR(VLOOKUP(H28, Level_Map!A:B, 2, FALSE), "") -> L4 | T28: =IFERROR(VLOOKUP(I28, Function_BU_Map!A:B, 2, FALSE), "") -> Tech | U28: =IF(G28="Working","Active","Exited") -> Active | V28: ="Q"&ROUNDUP(MONTH(C28)/3,0)&" "&YEAR(C28) -> Q1 2023 | W28: =IF(O28="","", "Q"&ROUNDUP(MONTH(O28)/3,0)&" "&YEAR(O28)) | X28: =IF(P28="","",YEAR(C28)) -> 2023
A29: EP1027 | B29: Employee 28 | C29: 45251 | D29: ep1027@example.com | E29: Male | F29: Permanent | G29: Working | H29: Manager | I29: CX | J29: Banking | K29: Training | M29: Mgr 12 | N29: Lead 19 | P29: Nov 2023 | R29: 1–2 years | S29: =IFERROR(VLOOKUP(H29, Level_Map!A:B, 2, FALSE), "") -> L5 | T29: =IFERROR(VLOOKUP(I29, Function_BU_Map!A:B, 2, FALSE), "") -> Ops | U29: =IF(G29="Working","Active","Exited") -> Active | V29: ="Q"&ROUNDUP(MONTH(C29)/3,0)&" "&YEAR(C29) -> Q4 2023 | W29: =IF(O29="","", "Q"&ROUNDUP(MONTH(O29)/3,0)&" "&YEAR(O29)) | X29: =IF(P29="","",YEAR(C29)) -> 2023
A30: EP1028 | B30: Employee 29 | C30: 44771 | D30: ep1028@example.com | E30: Female | F30: Permanent | G30: Working | H30: Senior Associate | I30: CX | J30: Ops Excellence | K30: Quality | M30: Mgr 2 | N30: Lead 21 | P30: Jul 2022 | R30: 2–4 years | S30: =IFERROR(VLOOKUP(H30, Level_Map!A:B, 2, FALSE), "") -> L4 | T30: =IFERROR(VLOOKUP(I30, Function_BU_Map!A:B, 2, FALSE), "") -> Ops | U30: =IF(G30="Working","Active","Exited") -> Active | V30: ="Q"&ROUNDUP(MONTH(C30)/3,0)&" "&YEAR(C30) -> Q3 2022 | W30: =IF(O30="","", "Q"&ROUNDUP(MONTH(O30)/3,0)&" "&YEAR(O30)) | X30: =IF(P30="","",YEAR(C30)) -> 2022
A31: EP1029 | B31: Employee 30 | C31: 44751 | D31: ep1029@example.com | E31: Male | F31: Permanent | G31: Working | H31: Manager | I31: CX | J31: Wealth | K31: Support | M31: Mgr 3 | N31: Lead 17 | P31: Jul 2022 | R31: 2–4 years | S31: =IFERROR(VLOOKUP(H31, Level_Map!A:B, 2, FALSE), "") -> L5 | T31: =IFERROR(VLOOKUP(I31, Function_BU_Map!A:B, 2, FALSE), "") -> Ops | U31: =IF(G31="Working","Active","Exited") -> Active | V31: ="Q"&ROUNDUP(MONTH(C31)/3,0)&" "&YEAR(C31) -> Q3 2022 | W31: =IF(O31="","", "Q"&ROUNDUP(MONTH(O31)/3,0)&" "&YEAR(O31)) | X31: =IF(P31="","",YEAR(C31)) -> 2022
A32: EP1030 | B32: Employee 31 | C32: 45340 | D32: ep1030@example.com | E32: Male | F32: Contractor | G32: Working | H32: Director | I32: CX | J32: Ops Excellence | K32: Quality | M32: Mgr 5 | N32: Lead 24 | P32: Feb 2024 | R32: 1–2 years | S32: =IFERROR(VLOOKUP(H32, Level_Map!A:B, 2, FALSE), "") -> L7 | T32: =IFERROR(VLOOKUP(I32, Function_BU_Map!A:B, 2, FALSE), "") -> Ops | U32: =IF(G32="Working","Active","Exited") -> Active | V32: ="Q"&ROUNDUP(MONTH(C32)/3,0)&" "&YEAR(C32) -> Q1 2024 | W32: =IF(O32="","", "Q"&ROUNDUP(MONTH(O32)/3,0)&" "&YEAR(O32)) | X32: =IF(P32="","",YEAR(C32)) -> 2024
A33: EP1031 | B33: Employee 32 | C33: 44760 | D33: ep1031@example.com | E33: Male | F33: Permanent | G33: Working | H33: Associate | I33: CX | J33: Wealth | K33: Support | M33: Mgr 1 | N33: Lead 3 | P33: Jul 2022 | R33: 2–4 years | S33: =IFERROR(VLOOKUP(H33, Level_Map!A:B, 2, FALSE), "") -> L3 | T33: =IFERROR(VLOOKUP(I33, Function_BU_Map!A:B, 2, FALSE), "") -> Ops | U33: =IF(G33="Working","Active","Exited") -> Active | V33: ="Q"&ROUNDUP(MONTH(C33)/3,0)&" "&YEAR(C33) -> Q3 2022 | W33: =IF(O33="","", "Q"&ROUNDUP(MONTH(O33)/3,0)&" "&YEAR(O33)) | X33: =IF(P33="","",YEAR(C33)) -> 2022
A34: EP1032 | B34: Employee 33 | C34: 45297 | D34: ep1032@example.com | E34: Male | F34: Permanent | G34: Relieved | H34: Senior Associate | I34: Data | J34: Banking | K34: Data Eng | M34: Mgr 15 | N34: Lead 22 | O34: 45679 | P34: Jan 2024 | Q34: Jan 2025 | R34: 1–2 years | S34: =IFERROR(VLOOKUP(H34, Level_Map!A:B, 2, FALSE), "") -> L4 | T34: =IFERROR(VLOOKUP(I34, Function_BU_Map!A:B, 2, FALSE), "") -> Tech | U34: =IF(G34="Working","Active","Exited") -> Exited | V34: ="Q"&ROUNDUP(MONTH(C34)/3,0)&" "&YEAR(C34) -> Q1 2024 | W34: =IF(O34="","", "Q"&ROUNDUP(MONTH(O34)/3,0)&" "&YEAR(O34)) -> Q1 2025 | X34: =IF(P34="","",YEAR(C34)) -> 2024
A35: EP1033 | B35: Employee 34 | C35: 45798 | D35: ep1033@example.com | E35: Male | F35: Permanent | G35: Relieved | H35: Senior Manager | I35: Product | J35: Cards | K35: Design | M35: Mgr 16 | N35: Lead 7 | O35: 45861 | P35: May 2025 | Q35: Jul 2025 | R35: <1 year | S35: =IFERROR(VLOOKUP(H35, Level_Map!A:B, 2, FALSE), "") -> L6 | T35: =IFERROR(VLOOKUP(I35, Function_BU_Map!A:B, 2, FALSE), "") -> Tech | U35: =IF(G35="Working","Active","Exited") -> Exited | V35: ="Q"&ROUNDUP(MONTH(C35)/3,0)&" "&YEAR(C35) -> Q2 2025 | W35: =IF(O35="","", "Q"&ROUNDUP(MONTH(O35)/3,0)&" "&YEAR(O35)) -> Q3 2025 | X35: =IF(P35="","",YEAR(C35)) -> 2025
A36: EP1034 | B36: Employee 35 | C36: 44650 | D36: ep1034@example.com | E36: Male | F36: Intern | G36: Relieved | H36: Analyst | I36: Marketing | J36: Ops Excellence | K36: Performance | M36: Mgr 4 | N36: Lead 13 | O36: 45620 | P36: Mar 2022 | Q36: Nov 2024 | R36: 2–4 years | S36: =IFERROR(VLOOKUP(H36, Level_Map!A:B, 2, FALSE), "") -> L1 | T36: =IFERROR(VLOOKUP(I36, Function_BU_Map!A:B, 2, FALSE), "") -> Growth | U36: =IF(G36="Working","Active","Exited") -> Exited | V36: ="Q"&ROUNDUP(MONTH(C36)/3,0)&" "&YEAR(C36) -> Q1 2022 | W36: =IF(O36="","", "Q"&ROUNDUP(MONTH(O36)/3,0)&" "&YEAR(O36)) -> Q4 2024 | X36: =IF(P36="","",YEAR(C36)) -> 2022
A37: EP1035 | B37: Employee 36 | C37: 45660 | D37: ep1035@example.com | E37: Male | F37: Permanent | G37: Relieved | H37: Director | I37: Product | J37: Wealth | K37: Design | M37: Mgr 2 | N37: Lead 2 | O37: 45753 | P37: Jan 2025 | Q37: Apr 2025 | R37: <1 year | S37: =IFERROR(VLOOKUP(H37, Level_Map!A:B, 2, FALSE), "") -> L7 | T37: =IFERROR(VLOOKUP(I37, Function_BU_Map!A:B, 2, FALSE), "") -> Tech | U37: =IF(G37="Working","Active","Exited") -> Exited | V37: ="Q"&ROUNDUP(MONTH(C37)/3,0)&" "&YEAR(C37) -> Q1 2025 | W37: =IF(O37="","", "Q"&ROUNDUP(MONTH(O37)/3,0)&" "&YEAR(O37)) -> Q2 2025 | X37: =IF(P37="","",YEAR(C37)) -> 2025
A38: EP1036 | B38: Employee 37 | C38: 45337 | D38: ep1036@example.com | E38: Male | F38: Permanent | G38: Working | H38: Associate | I38: Product | J38: Growth | K38: Design | M38: Mgr 17 | N38: Lead 20 | P38: Feb 2024 | R38: 1–2 years | S38: =IFERROR(VLOOKUP(H38, Level_Map!A:B, 2, FALSE), "") -> L3 | T38: =IFERROR(VLOOKUP(I38, Function_BU_Map!A:B, 2, FALSE), "") -> Tech | U38: =IF(G38="Working","Active","Exited") -> Active | V38: ="Q"&ROUNDUP(MONTH(C38)/3,0)&" "&YEAR(C38) -> Q1 2024 | W38: =IF(O38="","", "Q"&ROUNDUP(MONTH(O38)/3,0)&" "&YEAR(O38)) | X38: =IF(P38="","",YEAR(C38)) -> 2024
A39: EP1037 | B39: Employee 38 | C39: 44723 | D39: ep1037@example.com | E39: Male | F39: Permanent | G39: Working | H39: Senior Manager | I39: CX | J39: Cards | K39: Support | M39: Mgr 12 | N39: Lead 5 | P39: Jun 2022 | R39: 2–4 years | S39: =IFERROR(VLOOKUP(H39, Level_Map!A:B, 2, FALSE), "") -> L6 | T39: =IFERROR(VLOOKUP(I39, Function_BU_Map!A:B, 2, FALSE), "") -> Ops | U39: =IF(G39="Working","Active","Exited") -> Active | V39: ="Q"&ROUNDUP(MONTH(C39)/3,0)&" "&YEAR(C39) -> Q2 2022 | W39: =IF(O39="","", "Q"&ROUNDUP(MONTH(O39)/3,0)&" "&YEAR(O39)) | X39: =IF(P39="","",YEAR(C39)) -> 2022
A40: EP1038 | B40: Employee 39 | C40: 45692 | D40: ep1038@example.com | E40: Male | F40: Intern | G40: Working | H40: Manager | I40: Engineering | J40: Banking | K40: Frontend | M40: Mgr 13 | N40: Lead 18 | P40: Feb 2025 | R40: <1 year | S40: =IFERROR(VLOOKUP(H40, Level_Map!A:B, 2, FALSE), "") -> L5 | T40: =IFERROR(VLOOKUP(I40, Function_BU_Map!A:B, 2, FALSE), "") -> Tech | U40: =IF(G40="Working","Active","Exited") -> Active | V40: ="Q"&ROUNDUP(MONTH(C40)/3,0)&" "&YEAR(C40) -> Q1 2025 | W40: =IF(O40="","", "Q"&ROUNDUP(MONTH(O40)/3,0)&" "&YEAR(O40)) | X40: =IF(P40="","",YEAR(C40)) -> 2025
...

Sheet Employees
A1: Emp ID | B1: Full name | C1: Date of joining | D1: Email | E1: Gender | F1: Emp type | G1: Emp status | H1: Designation | I1: Function | J1: Team | K1: Department | L1: Sub department | M1: Reporting manager | N1: Lead POC | O1: Exit date | P1: Joining month | Q1: Exit month | R1: Tenure bracket
A2: EP1000 | B2: Employee 1 | C2: 45871 | D2: ep1000@example.com | E2: Male | F2: Contractor | G2: Relieved | H2: Senior Analyst | I2: Finance | J2: Ops Excellence | K2: FP&A | M2: Mgr 11 | N2: Lead 11 | O2: 45908 | P2: Aug 2025 | Q2: Sep 2025 | R2: <1 year
A3: EP1001 | B3: Employee 2 | C3: 44613 | D3: ep1001@example.com | E3: Female | F3: Permanent | G3: Working | H3: Senior Director | I3: Finance | J3: Ops Excellence | K3: Payroll | M3: Mgr 6 | N3: Lead 2 | P3: Feb 2022 | R3: 2–4 years
A4: EP1002 | B4: Employee 3 | C4: 45125 | D4: ep1002@example.com | E4: Male | F4: Permanent | G4: Working | H4: Associate | I4: Product | J4: Ops Excellence | K4: Design | M4: Mgr 10 | N4: Lead 16 | P4: Jul 2023 | R4: 2–4 years
A5: EP1003 | B5: Employee 4 | C5: 45063 | D5: ep1003@example.com | E5: Male | F5: Permanent | G5: Relieved | H5: Senior Associate | I5: Risk | J5: Wealth | K5: Collections | M5: Mgr 19 | N5: Lead 7 | O5: 45321 | P5: May 2023 | Q5: Jan 2024 | R5: <1 year
A6: EP1004 | B6: Employee 5 | C6: 44847 | D6: ep1004@example.com | E6: Male | F6: Permanent | G6: Relieved | H6: Associate | I6: Data | J6: Lending | K6: Data Eng | M6: Mgr 2 | N6: Lead 20 | O6: 45086 | P6: Oct 2022 | Q6: Jun 2023 | R6: <1 year
A7: EP1005 | B7: Employee 6 | C7: 45678 | D7: ep1005@example.com | E7: Male | F7: Permanent | G7: Working | H7: Director | I7: CX | J7: Banking | K7: Training | M7: Mgr 8 | N7: Lead 4 | P7: Jan 2025 | R7: <1 year
A8: EP1006 | B8: Employee 7 | C8: 44740 | D8: ep1006@example.com | E8: Male | F8: Permanent | G8: Working | H8: Senior Director | I8: CX | J8: Ops Excellence | K8: Quality | M8: Mgr 2 | N8: Lead 10 | P8: Jun 2022 | R8: 2–4 years
A9: EP1007 | B9: Employee 8 | C9: 45771 | D9: ep1007@example.com | E9: Female | F9: Permanent | G9: Working | H9: Analyst | I9: HR | J9: Wealth | K9: Talent Acquisition | M9: Mgr 16 | N9: Lead 13 | P9: Apr 2025 | R9: <1 year
A10: EP1008 | B10: Employee 9 | C10: 45426 | D10: ep1008@example.com | E10: Male | F10: Intern | G10: Relieved | H10: Associate | I10: Product | J10: Cards | K10: Product Mgmt | M10: Mgr 7 | N10: Lead 9 | O10: 45472 | P10: May 2024 | Q10: Jun 2024 | R10: <1 year
A11: EP1009 | B11: Employee 10 | C11: 44623 | D11: ep1009@example.com | E11: Female | F11: Permanent | G11: Working | H11: Manager | I11: Engineering | J11: Banking | K11: Platform | M11: Mgr 1 | N11: Lead 5 | P11: Mar 2022 | R11: 2–4 years
A12: EP1010 | B12: Employee 11 | C12: 44753 | D12: ep1010@example.com | E12: Female | F12: Permanent | G12: Relieved | H12: Associate | I12: HR | J12: Wealth | K12: People Ops | M12: Mgr 5 | N12: Lead 3 | O12: 45230 | P12: Jul 2022 | Q12: Oct 2023 | R12: 1–2 years
A13: EP1011 | B13: Employee 12 | C13: 45038 | D13: ep1011@example.com | E13: Female | F13: Permanent | G13: Working | H13: Senior Director | I13: CX | J13: Ops Excellence | K13: Training | M13: Mgr 5 | N13: Lead 23 | P13: Apr 2023 | R13: 2–4 years
A14: EP1012 | B14: Employee 13 | C14: 45596 | D14: ep1012@example.com | E14: Female | F14: Permanent | G14: Relieved | H14: Analyst | I14: CX | J14: Lending | K14: Training | M14: Mgr 7 | N14: Lead 17 | O14: 45934 | P14: Oct 2024 | Q14: Oct 2025 | R14: <1 year
A15: EP1013 | B15: Employee 14 | C15: 44616 | D15: ep1013@example.com | E15: Male | F15: Permanent | G15: Relieved | H15: Senior Associate | I15: HR | J15: Ops Excellence | K15: L&D | M15: Mgr 13 | N15: Lead 7 | O15: 45795 | P15: Feb 2022 | Q15: May 2025 | R15: 2–4 years
A16: EP1014 | B16: Employee 15 | C16: 44969 | D16: ep1014@example.com | E16: Male | F16: Permanent | G16: Working | H16: Manager | I16: HR | J16: Growth | K16: People Ops | M16: Mgr 12 | N16: Lead 12 | P16: Feb 2023 | R16: 2–4 years
A17: EP1015 | B17: Employee 16 | C17: 45892 | D17: ep1015@example.com | E17: Male | F17: Consultant | G17: Working | H17: Associate | I17: Product | J17: Wealth | K17: Research | M17: Mgr 1 | N17: Lead 20 | P17: Aug 2025 | R17: <1 year
A18: EP1016 | B18: Employee 17 | C18: 45678 | D18: ep1016@example.com | E18: Male | F18: Permanent | G18: Working | H18: Senior Associate | I18: Engineering | J18: Cards | K18: Platform | M18: Mgr 10 | N18: Lead 12 | P18: Jan 2025 | R18: <1 year
A19: EP1017 | B19: Employee 18 | C19: 45421 | D19: ep1017@example.com | E19: Male | F19: Permanent | G19: Relieved | H19: Associate | I19: Engineering | J19: Cards | K19: QA | M19: Mgr 12 | N19: Lead 7 | O19: 45563 | P19: May 2024 | Q19: Sep 2024 | R19: <1 year
A20: EP1018 | B20: Employee 19 | C20: 45481 | D20: ep1018@example.com | E20: Male | F20: Permanent | G20: Working | H20: Manager | I20: Product | J20: Banking | K20: Product Mgmt | M20: Mgr 5 | N20: Lead 1 | P20: Jul 2024 | R20: 1–2 years
A21: EP1019 | B21: Employee 20 | C21: 45768 | D21: ep1019@example.com | E21: Female | F21: Permanent | G21: Working | H21: Senior Analyst | I21: CX | J21: Growth | K21: Quality | M21: Mgr 11 | N21: Lead 24 | P21: Apr 2025 | R21: <1 year
A22: EP1020 | B22: Employee 21 | C22: 45131 | D22: ep1020@example.com | E22: Male | F22: Permanent | G22: Working | H22: Associate | I22: Product | J22: Growth | K22: Design | M22: Mgr 16 | N22: Lead 1 | P22: Jul 2023 | R22: 2–4 years
A23: EP1021 | B23: Employee 22 | C23: 44575 | D23: ep1021@example.com | E23: Male | F23: Permanent | G23: Relieved | H23: Associate | I23: Finance | J23: Wealth | K23: Accounting | M23: Mgr 3 | N23: Lead 19 | O23: 44931 | P23: Jan 2022 | Q23: Jan 2023 | R23: <1 year
A24: EP1022 | B24: Employee 23 | C24: 45427 | D24: ep1022@example.com | E24: Male | F24: Permanent | G24: Working | H24: Senior Manager | I24: Data | J24: Lending | K24: Data Science | M24: Mgr 18 | N24: Lead 23 | P24: May 2024 | R24: 1–2 years
A25: EP1023 | B25: Employee 24 | C25: 45258 | D25: ep1023@example.com | E25: Male | F25: Permanent | G25: Working | H25: Senior Director | I25: Engineering | J25: Lending | K25: QA | M25: Mgr 17 | N25: Lead 2 | P25: Nov 2023 | R25: 1–2 years
A26: EP1024 | B26: Employee 25 | C26: 45131 | D26: ep1024@example.com | E26: Other | F26: Contractor | G26: Working | H26: Senior Analyst | I26: CX | J26: Cards | K26: Training | M26: Mgr 16 | N26: Lead 3 | P26: Jul 2023 | R26: 2–4 years
A27: EP1025 | B27: Employee 26 | C27: 44880 | D27: ep1025@example.com | E27: Female | F27: Permanent | G27: Working | H27: Senior Analyst | I27: HR | J27: Cards | K27: L&D | M27: Mgr 3 | N27: Lead 16 | P27: Nov 2022 | R27: 2–4 years
A28: EP1026 | B28: Employee 27 | C28: 45002 | D28: ep1026@example.com | E28: Male | F28: Permanent | G28: Working | H28: Senior Associate | I28: Engineering | J28: Growth | K28: QA | M28: Mgr 16 | N28: Lead 9 | P28: Mar 2023 | R28: 2–4 years
A29: EP1027 | B29: Employee 28 | C29: 45251 | D29: ep1027@example.com | E29: Male | F29: Permanent | G29: Working | H29: Manager | I29: CX | J29: Banking | K29: Training | M29: Mgr 12 | N29: Lead 19 | P29: Nov 2023 | R29: 1–2 years
A30: EP1028 | B30: Employee 29 | C30: 44771 | D30: ep1028@example.com | E30: Female | F30: Permanent | G30: Working | H30: Senior Associate | I30: CX | J30: Ops Excellence | K30: Quality | M30: Mgr 2 | N30: Lead 21 | P30: Jul 2022 | R30: 2–4 years
A31: EP1029 | B31: Employee 30 | C31: 44751 | D31: ep1029@example.com | E31: Male | F31: Permanent | G31: Working | H31: Manager | I31: CX | J31: Wealth | K31: Support | M31: Mgr 3 | N31: Lead 17 | P31: Jul 2022 | R31: 2–4 years
A32: EP1030 | B32: Employee 31 | C32: 45340 | D32: ep1030@example.com | E32: Male | F32: Contractor | G32: Working | H32: Director | I32: CX | J32: Ops Excellence | K32: Quality | M32: Mgr 5 | N32: Lead 24 | P32: Feb 2024 | R32: 1–2 years
A33: EP1031 | B33: Employee 32 | C33: 44760 | D33: ep1031@example.com | E33: Male | F33: Permanent | G33: Working | H33: Associate | I33: CX | J33: Wealth | K33: Support | M33: Mgr 1 | N33: Lead 3 | P33: Jul 2022 | R33: 2–4 years
A34: EP1032 | B34: Employee 33 | C34: 45297 | D34: ep1032@example.com | E34: Male | F34: Permanent | G34: Relieved | H34: Senior Associate | I34: Data | J34: Banking | K34: Data Eng | M34: Mgr 15 | N34: Lead 22 | O34: 45679 | P34: Jan 2024 | Q34: Jan 2025 | R34: 1–2 years
A35: EP1033 | B35: Employee 34 | C35: 45798 | D35: ep1033@example.com | E35: Male | F35: Permanent | G35: Relieved | H35: Senior Manager | I35: Product | J35: Cards | K35: Design | M35: Mgr 16 | N35: Lead 7 | O35: 45861 | P35: May 2025 | Q35: Jul 2025 | R35: <1 year
A36: EP1034 | B36: Employee 35 | C36: 44650 | D36: ep1034@example.com | E36: Male | F36: Intern | G36: Relieved | H36: Analyst | I36: Marketing | J36: Ops Excellence | K36: Performance | M36: Mgr 4 | N36: Lead 13 | O36: 45620 | P36: Mar 2022 | Q36: Nov 2024 | R36: 2–4 years
A37: EP1035 | B37: Employee 36 | C37: 45660 | D37: ep1035@example.com | E37: Male | F37: Permanent | G37: Relieved | H37: Director | I37: Product | J37: Wealth | K37: Design | M37: Mgr 2 | N37: Lead 2 | O37: 45753 | P37: Jan 2025 | Q37: Apr 2025 | R37: <1 year
A38: EP1036 | B38: Employee 37 | C38: 45337 | D38: ep1036@example.com | E38: Male | F38: Permanent | G38: Working | H38: Associate | I38: Product | J38: Growth | K38: Design | M38: Mgr 17 | N38: Lead 20 | P38: Feb 2024 | R38: 1–2 years
A39: EP1037 | B39: Employee 38 | C39: 44723 | D39: ep1037@example.com | E39: Male | F39: Permanent | G39: Working | H39: Senior Manager | I39: CX | J39: Cards | K39: Support | M39: Mgr 12 | N39: Lead 5 | P39: Jun 2022 | R39: 2–4 years
A40: EP1038 | B40: Employee 39 | C40: 45692 | D40: ep1038@example.com | E40: Male | F40: Intern | G40: Working | H40: Manager | I40: Engineering | J40: Banking | K40: Frontend | M40: Mgr 13 | N40: Lead 18 | P40: Feb 2025 | R40: <1 year
...

Sheet Level_Map
A1: Designation | B1: Level_map
A2: Analyst | B2: L1
A3: Senior Analyst | B3: L2
A4: Associate | B4: L3
A5: Senior Associate | B5: L4
A6: Manager | B6: L5
A7: Senior Manager | B7: L6
A8: Director | B8: L7
A9: Senior Director | B9: L8

Sheet Function_BU_Map
A1: Function | B1: BU
A2: Engineering | B2: Tech
A3: Product | B3: Tech
A4: CX | B4: Ops
A5: Risk | B5: Risk
A6: Finance | B6: Corp
A7: Marketing | B7: Growth
A8: HR | B8: Corp
A9: Data | B9: Tech
